Workbook
Name IQ_CH: 110000
Name IQ_CQ: 5000
Name IQ_CY: 10000
Name IQ_DAILY: 500000
Name IQ_FH: 100000
Name IQ_FQ: 500
Name IQ_FY: 1000
Name IQ_LTM: 2000
Name IQ_MONTH: 15000
Name IQ_NTM: 6000
Name IQ_WEEK: 50000
Name IQ_YTD: 3000

Sheet PB_CACHE
A1: H4sIAAAAAAAEAM2QQUvDMBTHu1Wxoh8id0toa+fcoRerKLjDpMXLGDMNDxuWJjVJhe5j+IU1KZ0ePHj1BfJeAv/f+/P3Jp7nfdpy3dX51F5PK2ZofSPlDpV9CxotWaWI6kP0DEozKbIkShKc4hhHIco7bjoFmYDOKMJDtOoqzugj9KXcgchEx/mx4xff2O2A3Y5YXIBihLM9qTjkhNbw++eilO0S3oEPr1tGjbVhtb7lnoyuglw2LVGgggei64LtwfO94GNS9NpAg3PJOQw6je9B2A300O/eOrvN9AfAS7xej6rCKCZeQ9RoKhVn1U8GKY7c+TuAaj4nMzq7iheXKUTXi80mmI5xn/rjcOSG/2jVmTv7At67jZonAgAA

Sheet Data-Cons
A1: Tyson vs. Smithfield Financials
A2: Tyson Prepared Foods + Pork
A3: Company | B3: Tys Period | C3: Smfd Period | D3: Sales | E3: Seg Prof | F3: Volume
A4: Tyson | B4: 2Q21 | C4: Q1 2021 | D4: =2164+1477 -> 3641 | E4: =217+67 -> 284
A5: Tyson | B5: 3Q21 | C5: Q2 2021 | D5: =2323+1715 -> 4038 | E5: =150+67 -> 217
A6: Tyson | B6: 4Q21 | C6: Q3 2021 | D6: =2253+1646 -> 3899 | E6: =39+78 -> 117
A7: Tyson | B7: 2Q22 | C7: Q1 2022 | D7: =2393+1565 -> 3958 | E7: =263+59 -> 322
A8: Tyson | B8: 3Q22 | C8: Q2 2022 | D8: =2447+1619 -> 4066 | E8: =186+25 -> 211
A9: Tyson | B9: 4Q22 | C9: Q3 2022 | D9: =2516+1604 -> 4120 | E9: =147-50 -> 97
A10: Tyson | B10: 1Q23 | C10: Q4 2022
A11: Tyson | B11: 1H21 | C11: Q4&Q1 2021 | D11: 4277 | E11: 483
A12: Tyson | B12: Q2&Q321 | C12: H1 2021 | D12: =D5+D4 -> 7679 | E12: =E5+E4 -> 501
A13: Tyson | B13: 1H22 | C13: Q4&Q1 2022 | D13: 4726 | E13: 449
A14: Tyson | B14: Q2&Q322 | C14: H1 2022 | D14: =D8+D7 -> 8024 | E14: =E8+E7 -> 533
A15: Tyson | B15: Q1 - Q3 | C15: Lst 3 Qtr 21 | D15: =D11+D5 -> 8315 | E15: =E11+E5 -> 700 | F15: =2.67*1000 -> 2670
A16: Tyson | B16: Q1 - Q3 | C16: Lst 3 Qtr 22 | D16: =D13+D8 -> 8792 | E16: =E13+E8 -> 660 | F16: =2.52*1000 -> 2520
A17: Tyson | B17: Q1 - Q4 | C17: Lst 4 Qtr 21 | D17: =D11+D5+D6 -> 12214 | E17: =E11+E5+E6 -> 817
A18: Tyson | B18: Q1 - Q4 | C18: Lst 4 Qtr 22 | D18: =D13+D9+D8 -> 12912 | E18: =E13+E9+E8 -> 757
A21: Company | B21: Tys Period | C21: Smfd Period | D21: Sales | E21: Seg Prof | F21: Volume
A22: Smithfield | B22: Q3 2020 | C22: Q4 2020 | D22: 3587.2 | E22: -8.322
A23: Smithfield | B23: 2Q21 | C23: Q1 2021 | D23: 3441.627 | E23: 196.961
A24: Smithfield | B24: 3Q21 | C24: Q2 2021 | D24: 3717.272 | E24: 192.549
A25: Smithfield | B25: 4Q21 | C25: Q3 2021 | D25: 3567.2541 | E25: 203.5
A26: Smithfield | B26: Q3 2021 | C26: Q4 2021 | D26: 3877.006 | E26: 383.8 | P26: Calendar | Q26: Q4 2021 | R26: Q1 | S26: Q2 | T26: Q3 | U26: Q4 | V26: 2022
A27: Smithfield | B27: 2Q22 | C27: Q1 2022 | D27: 3620.122 | E27: 349.5 | P27: Smithfield | Q27: Q4 2021 | R27: Q1 2022 | S27: Q2 2022 | T27: Q3 2022 | U27: Q4 2022 | V27: FY 2022
A28: Smithfield | B28: 3Q22 | C28: Q2 2022 | D28: 3743.2 | E28: 293.6 | P28: Tyson | Q28: Q1 2022 | R28: Q2 2022 | S28: Q3 2022 | T28: Q4 2022 | U28: Q1 2023 | V28: FY 2022
A29: Smithfield | B29: 4Q22 | C29: Q3 2022 | D29: 3645.2 | E29: 169.2 | P29: Hormel | Q29: Nov-Jan | R29: Feb-Apr | S29: May-Jul | T29: Aug-Oct | U29: Nov-Jan | V29: FY 2022
A30: Smithfield | B30: 1Q23 | C30: Q4 2022
A31: Smithfield | B31: 1H21 | C31: Q4&Q1 2021 | D31: =D23+D22 -> 7028.827 | E31: =E23+E22 -> 188.639 | F31: =F23+F22 -> 0
A32: Smithfield | B32: Q2&Q321 | C32: H1 2021 | D32: =D24+D23 -> 7158.899 | E32: =E24+E23 -> 389.51 | F32: =F24+F23 -> 0
A33: Smithfield | B33: 1H22 | C33: Q4&Q1 2022 | D33: =D27+D26 -> 7497.128 | E33: =E27+E26 -> 733.3 | F33: =F27+F26 -> 0
A34: Smithfield | B34: Q2&Q322 | C34: H1 2022 | D34: =D28+D27 -> 7363.322 | E34: =E28+E27 -> 643.1 | F34: =F28+F27 -> 0
A35: Smithfield | B35: Q1 - Q3 | C35: Lst 3 Qtr 21 | D35: =D24+D23+D22 -> 10746.099 | E35: =E24+E23+E22 -> 381.188 | F35: =F24+F23+F22 -> 0
A36: Smithfield | B36: Q1 - Q3 | C36: Lst 3 Qtr 22 | D36: =D28+D27+D26 -> 11240.328 | E36: =E28+E27+E26 -> 1026.9 | F36: =F28+F27+F26 -> 0
A37: Smithfield | B37: Q1 - Q4 | C37: Lst 4 Qtr 21 | D37: =D25+D24+D23+D22 -> 14313.353 | E37: =E25+E24+E23+E22 -> 584.688 | F37: =F25+F24+F23+F22 -> 0
A38: Smithfield | B38: Q1 - Q4 | C38: Lst 4 Qtr 22 | D38: =D29+D28+D27+D26 -> 14885.528 | E38: =E29+E28+E27+E26 -> 1196.1 | F38: =F29+F28+F27+F26 -> 0
A42: Company | B42: JBS Period | C42: Smfd Period | D42: Sales | E42: Seg Prof | F42: Volume
A43: JBS | B43: Q421 - Q322 | C43: Lst 4 Qtr 22 | D43: 6149.1164 | E43: 579.44621
A44: JBS | B44: Q121 - Q322 | C44: Lst 4 Qtr 21 | D44: 5728.6088 | E44: 555.89991
A45: JBS | B45: 3Q22 | C45: Q3 2022 | D45: 2127.4865 | E45: 141.15652
...

Sheet Q4 2025
B1: Smithfield Packaged Comparison to Tyson Prepared Foods and Hormel Retail + Foodservice
T5: Tyson | U5: Period | V5: Tyson Sales | W5: Tyson Op Prof | X5: Op Mgn | Y5: Volume | Z5: ASP
T6: Q4 2024 | U6: Q4 2024 | V6: ='Data-PM vs PF'!D19 -> 2473 | W6: ='Data-PM vs PF'!E19 -> 283 | X6: =W6/V6 -> 0.11443591
T7: Q1 2026 | U7: Q4 2025 | V7: ='Data-PM vs PF'!D23 -> 2673 | W7: ='Data-PM vs PF'!E23 -> 278 | X7: =W7/V7 -> 0.10400299
T8: ='Data-PM vs PF'!B24 -> Q123 - Q423 | U8: ='Data-PM vs PF'!C24 -> Lst 4 Qtr PY | V8: ='Data-PM vs PF'!D24 -> 9781 | W8: ='Data-PM vs PF'!E24 -> 1248 | X8: =W8/V8 -> 0.12759432
T9: ='Data-PM vs PF'!B25 -> Q124 - Q424 | U9: ='Data-PM vs PF'!C25 -> Lst 4 Qtr CY | V9: ='Data-PM vs PF'!D25 -> 10130 | W9: ='Data-PM vs PF'!E25 -> 1263 | X9: =W9/V9 -> 0.12467917
T10: Change | U10: Q4 | V10: =(V7-V6)/V6 -> 0.080873433 | W10: =(W7-W6)/W6 -> -0.017667845 | X10: =(X7-X6)/X6 -> -0.091168193
U11: Lst 4 Qtr | V11: =(V9-V8)/V8 -> 0.035681423 | W11: =(W9-W8)/W8 -> 0.012019231 | X11: =(X9-X8)/X8 -> -0.02284698
T15: Hormel | U15: Period | V15: HRL Sales | W15: HRL Op Prof | X15: Op Mgn | Y15: Volume | Z15: ASP
T16: Q324 | U16: Q424 | V16: ='Data-PM vs PF'!D70 -> 2820.318 | W16: ='Data-PM vs PF'!E70 -> 257.973 | X16: =W16/V16 -> 0.091469473
T17: Q325 | U17: Q425 | V17: ='Data-PM vs PF'!D74 -> 2846.033 | W17: ='Data-PM vs PF'!E74 -> 252.731 | X17: =W17/V17 -> 0.088801149
T18: Q122-Q422 | U18: =U28 -> Lst 4 Qtr PY | V18: ='Data-PM vs PF'!D75 -> 11215.228 | W18: ='Data-PM vs PF'!E75 -> 1117.365 | X18: =W18/V18 -> 0.099629272
T19: Q123 - Q423 | U19: =U29 -> Lst 4 Qtr CY | V19: ='Data-PM vs PF'!D76 -> 11427.45 | W19: ='Data-PM vs PF'!E76 -> 1045.328 | X19: =W19/V19 -> 0.091475176
T20: Change | U20: =U10 -> Q4 | V20: =(V17-V16)/V16 -> 0.0091177662 | W20: =(W17-W16)/W16 -> -0.020319956 | X20: =(X17-X16)/X16 -> -0.029171741
U21: Lst 4 Qtr | V21: =(V19-V18)/V18 -> 0.018922665 | W21: =(W19-W18)/W18 -> -0.064470428 | X21: =(X19-X18)/X18 -> -0.081844379
T25: SMFD Period | U25: Period | V25: Smfd Sales | W25: Smfd Seg Prof | X25: Op Mgn | Y25: Volume | Z25: ASP | AA25: Growth
B26: SP Mgn | C26: =I26 -> Q4 2024 | D26: =J26 -> Q4 2025 | E26: =K26 -> Lst 4 Qtr PY | F26: =L26 -> Lst 4 Qtr CY | H26: SP Mgn | I26: =U26 -> Q4 2024 | J26: =U27 -> Q4 2025 | K26: =U28 -> Lst 4 Qtr PY | L26: =U29 -> Lst 4 Qtr CY | N26: SP Mgn | O26: =I26 -> Q4 2024 | P26: =J26 -> Q4 2025 | Q26: =K26 -> Lst 4 Qtr PY | R26: =L26 -> Lst 4 Qtr CY | T26: =U6 -> Q4 2024 | U26: =U6 -> Q4 2024 | V26: ='Data-PM vs PF'!D45 -> 2458.2723 | W26: ='Data-PM vs PF'!E45 -> 313.39505 | X26: =W26/V26 -> 0.1274859
B27: Sales | C27: =V26 -> 2458.2723 | D27: =V27 -> 2563.4938 | E27: =V28 -> 8319.0159 | F27: =V29 -> 8756.3149 | H27: Sales | I27: =V6 -> 2473 | J27: =V7 -> 2673 | K27: =V8 -> 9781 | L27: =V9 -> 10130 | N27: Sales | O27: =V16 -> 2820.318 | P27: =V17 -> 2846.033 | Q27: =V18 -> 11215.228 | R27: =V19 -> 11427.45 | T27: =U7 -> Q4 2025 | U27: =U7 -> Q4 2025 | V27: ='Data-PM vs PF'!D49 -> 2563.4938 | W27: ='Data-PM vs PF'!E49 -> 301.66528 | X27: =W27/V27 -> 0.1176774
B28: Seg Prof | C28: =W26 -> 313.39505 | D28: =W27 -> 301.66528 | E28: =W28 -> 1129.8065 | F28: =W29 -> 1089.267 | H28: Seg Prof | I28: =W6 -> 283 | J28: =W7 -> 278 | K28: =W8 -> 1248 | L28: =W9 -> 1263 | N28: Seg Prof | O28: =W16 -> 257.973 | P28: =W17 -> 252.731 | Q28: =W18 -> 1117.365 | R28: =W19 -> 1045.328 | T28: ='Data-PM vs PF'!B50 -> Q1 - Q4 | U28: ='Data-PM vs PF'!C50 -> Lst 4 Qtr PY | V28: ='Data-PM vs PF'!D50 -> 8319.0159 | W28: ='Data-PM vs PF'!E50 -> 1129.8065 | X28: =W28/V28 -> 0.13581012
B29: SP Mgn % | C29: =C28/C27 -> 0.1274859 | D29: =D28/D27 -> 0.1176774 | E29: =E28/E27 -> 0.13581012 | F29: =F28/F27 -> 0.12439787 | H29: SP Mgn % | I29: =I28/I27 -> 0.11443591 | J29: =J28/J27 -> 0.10400299 | K29: =K28/K27 -> 0.12759432 | L29: =L28/L27 -> 0.12467917 | N29: SP Mgn % | O29: =O28/O27 -> 0.091469473 | P29: =P28/P27 -> 0.088801149 | Q29: =Q28/Q27 -> 0.099629272 | R29: =R28/R27 -> 0.091475176 | T29: ='Data-PM vs PF'!B51 -> Q1 - Q4 | U29: ='Data-PM vs PF'!C51 -> Lst 4 Qtr CY | V29: ='Data-PM vs PF'!D51 -> 8756.3149 | W29: ='Data-PM vs PF'!E51 -> 1089.267 | X29: =W29/V29 -> 0.12439787
T30: Change | U30: Q3 | V30: =(V27-V26)/V26 -> 0.042803034 | W30: =(W27-W26)/W26 -> -0.037428054 | X30: =(X27-X26)/X26 -> -0.076937912
U31: Lst 4 Qtr | V31: =(V29-V28)/V28 -> 0.052566189 | W31: =(W29-W28)/W28 -> -0.035881867 | X31: =(X29-X28)/X28 -> -0.084030873

Sheet Data-PM vs PF
A1: Tyson vs. Smithfield Financials Prepared Foods vs. Packaged
A2: Tyson Prepared Foods | I2: Calendar | J2: Q4 2021 | K2: Q1 | L2: Q2 | M2: Q3 | N2: Q4 | O2: 2022
A3: Company | B3: Tys Period | C3: Smfd Period | D3: Sales | E3: Seg Prof | F3: Volume | I3: Smithfield | J3: Q4 2021 | K3: Q1 2022 | L3: Q2 2022 | M3: Q3 2022 | N3: Q4 2022 | O3: FY 2022
A4: Tyson | B4: 2Q21 | C4: Q1 2021 | D4: 2164 | E4: 217 | I4: Tyson | J4: Q1 2022 | K4: Q2 2022 | L4: Q3 2022 | M4: Q4 2022 | N4: Q1 2023 | O4: FY 2022
A5: Tyson | B5: 3Q21 | C5: Q2 2021 | D5: 2323 | E5: 150 | I5: Hormel | J5: Nov-Jan | K5: Feb-Apr | L5: May-Jul | M5: Aug-Oct | N5: Nov-Jan | O5: FY 2022
A6: Tyson | B6: 4Q21 | C6: Q3 2021 | D6: 2253 | E6: 39
A7: Tyson | B7: 1Q22 | C7: Q4 2021 | D7: 2333 | E7: 186
A8: Tyson | B8: 2Q22 | C8: Q1 2022 | D8: 2393 | E8: 263
A9: Tyson | B9: 3Q22 | C9: Q2 2022 | D9: 2447 | E9: 186
A10: Tyson | B10: 4Q22 | C10: Q3 2022 | D10: 2516 | E10: 147
A11: Tyson | B11: 1Q23 | C11: Q4 2022 | D11: 2538 | E11: 266
A12: Tyson | B12: 2Q23 | C12: Q1 2023 | D12: 2422 | E12: 341 | I12: 341 | J12: 336 | K12: 303 | L12: 238 | M12: 353 | N12: 323 | O12: 289 | P12: 283 | Q12: 322 | R12: 329 | S12: 334 | T12: 278
A13: Tyson | B13: 3Q23 | C13: Q2 2023 | D13: 2383 | E13: 336
A14: Tyson | B14: 4Q23 | C14: Q3 2023 | D14: 2502 | E14: 303
A15: Tyson | B15: 1Q24 | C15: Q4 2023 | D15: 2543 | E15: 238
A16: Tyson | B16: 2Q24 | C16: Q1 2024 | D16: 2404 | E16: 353
A17: Tyson | B17: 3Q24 | C17: Q2 2024 | D17: 2432 | E17: 323
A18: Tyson | B18: 4Q24 | C18: Q3 2024 | D18: 2472 | E18: 289
A19: Tyson | B19: 1Q25 | C19: Q4 2024 | D19: 2473 | E19: 283
A20: Tyson | B20: 2Q25 | C20: Q1 2025 | D20: 2396 | E20: 322
A21: Tyson | B21: 3Q25 | C21: Q2 2025 | D21: 2515 | E21: 329
A22: Tyson | B22: 4Q25 | C22: Q3 2025 | D22: 2546 | E22: 334
A23: Tyson | B23: 1Q26 | C23: Q4 2025 | D23: 2673 | E23: 278
A24: Tyson | B24: Q123 - Q423 | C24: Lst 4 Qtr PY | D24: =SUM(D16:D19) -> 9781 | E24: =SUM(E16:E19) -> 1248
A25: Tyson | B25: Q124 - Q424 | C25: Lst 4 Qtr CY | D25: =SUM(D20:D23) -> 10130 | E25: =SUM(E20:E23) -> 1263
A28: Company | B28: Tys Period | C28: Smfd Period | D28: Sales | E28: Seg Prof | F28: Volume
A29: Smithfield | B29: Q1 2021 | C29: Q4 2020 | D29: 2171.7 | E29: 175.8
A30: Smithfield | B30: 2Q21 | C30: Q1 2021 | D30: =1916.527-36.626 -> 1879.901 | E30: =191.961-6.4 -> 185.561
A31: Smithfield | B31: 3Q21 | C31: Q2 2021 | D31: =1956.545-40.925 -> 1915.62 | E31: =163.5486262-5.96 -> 157.58863
A32: Smithfield | B32: 4Q21 | C32: Q3 2021 | D32: =2077.078-40.154 -> 2036.924 | E32: =164.5937557-3.813 -> 160.78076
A33: Smithfield | B33: Q3 2021 | C33: Q4 2021 | D33: =2565.284-42.069 -> 2523.215 | E33: =358.4176896-4.67 -> 353.74769
A34: Smithfield | B34: 2Q22 | C34: Q1 2022 | D34: =2233-48.168 -> 2184.832 | E34: =300.2-7.77 -> 292.43
A35: Smithfield | B35: 3Q22 | C35: Q2 2022 | D35: =2196.279-51.568 -> 2144.711 | E35: =235.699-6.48 -> 229.219
A36: Smithfield | B36: 4Q22 | C36: Q3 2022 | D36: =2195.2-51.979 -> 2143.221 | E36: =202.992-7.96 -> 195.032
A37: Smithfield | B37: 1Q23 | C37: Q4 2022 | D37: =2637.481-15.577 -> 2621.904 | E37: =308.019-2.08 -> 305.939
A38: Smithfield | B38: 2Q23 | C38: Q1 2023 | D38: 2076 | E38: 300.54066
A39: Smithfield | B39: 3Q23 | C39: Q2 2023 | D39: 1871.6002 | E39: 275.79108
A40: Smithfield | B40: 4Q23 | C40: Q3 2023 | D40: 1927.9831 | E40: 183.68495
A41: Smithfield | B41: 1Q24 | C41: Q4 2023 | D41: 2404.3701 | E41: 306.02961
A42: Smithfield | B42: 2Q24 | C42: Q1 2024 | D42: 1999.3755 | E42: 285.60374
...

Sheet Q2 2022 (Spec)
B1: Smithfield Packaged Meats Comparison to Tyson
B2: Tyson Results have been converted to Smithfield's Calendar
B3: Dollars in Millions
N6: Tyson | O6: Period | P6: Tyson Sales | Q6: Tyson Op Prof | R6: Tyson Op Prof | S6: Op Mgn | T6: Volume | U6: ASP
N7: Q1 2021 | O7: TYS Q2 21 | P7: ='Data-Cons'!D5 -> 4038 | Q7: ='Data-Cons'!E5 -> 217 | R7: ='Data-Cons'!#REF! -> #REF! | S7: =Q7/P7 -> 0.053739475 | U7: =P7/T7*100 -> #DIV/0!
N8: Q1 2022 | O8: TYS Q2 22 | P8: ='Data-Cons'!D8 -> 4066 | Q8: ='Data-Cons'!E8 -> 211 | R8: ='Data-Cons'!#REF! -> #REF! | S8: =Q8/P8 -> 0.051893753 | U8: =P8/T8*100 -> #DIV/0!
N9: Q1 2021 | O9: HML Q2 21 | P9: 1624.641 | Q9: 153.216 | R9: 153.216 | S9: 0.094307604 | T9: 591.143 | U9: 274.83046
N10: Q1 2022 | O10: HML Q2 22 | P10: 1660.257 | Q10: 177.109 | R10: 177.109 | S10: 0.10667565 | T10: 484.271 | U10: 342.83635
N11: Q2 2021 | O11: SFD Q2 21 | P11: 1956.5 | Q11: 163.5 | R11: 169 | S11: 0.086378738 | T11: 700.97386 | U11: 279.11169
N12: Q2 2022 | O12: SFD Q2 22 | P12: 2196.3 | Q12: 235.7 | R12: 220.7 | S12: 0.10048718 | T12: 703.17995 | U12: 312.33826
B17: Sales Development | E17: Vol Chg | F17: Price | H17: Adj Op Mgn | I17: =O41 -> Q2 2021 | J17: =O42 -> Q2 2022 | K17: =O43 -> Lst 3 Qtr 21 | L17: =O44 -> Lst 3 Qtr 22
B18: Q2 2022 vs. Q2 2021 | E18: =T12 -> 703.17995 | F18: =U12 -> 312.33826 | H18: Sales | I18: =P7 -> 4038 | J18: =P8 -> 4066 | K18: =P9 -> 1624.641 | L18: =P10 -> 1660.257
B19: Lst 3 Qtr 2022 vs. Lst 3 Qtr 2021 | E19: =T13 -> 0 | F19: =U13 -> 0 | H19: OP Profit | I19: =Q7 -> 217 | J19: =Q8 -> 211 | K19: =Q9 -> 153.216 | L19: =Q10 -> 177.109
H20: Op Mgn % | I20: =I19/I18 -> 0.053739475 | J20: =J19/J18 -> 0.051893753 | K20: =K19/K18 -> 0.094307604 | L20: =L19/L18 -> 0.10667565
N23: Hormel | O23: Period | P23: Hormel Sales | Q23: Hormel Op Prof | R23: Hormel Op Prof | S23: Op Mgn | T23: Volume | U23: ASP
N24: Q1 2021 | O24: Q2 2021 | P24: ='Data-Cons'!E45 -> 141.15652 | Q24: ='Data-Cons'!E46 -> 170.1756 | R24: ='Data-Cons'!#REF! -> #REF! | S24: =Q24/P24 -> 1.2055809 | T24: ='Data-Cons'!F46 -> 0 | U24: =P24/T24*100 -> #DIV/0!
N25: Q1 2022 | O25: Q2 2022 | P25: ='Data-Cons'!D45 -> 2127.4865 | Q25: ='Data-Cons'!#REF! -> #REF! | R25: ='Data-Cons'!#REF! -> #REF! | S25: =Q25/P25 -> #REF! | T25: ='Data-Cons'!F45 -> 0 | U25: =P25/T25*100 -> #DIV/0!
N26: Q4&Q1 2021 | O26: Lst 3 Qtr 21 | P26: ='Data-Cons'!D44 -> 5728.6088 | Q26: ='Data-Cons'!E44 -> 555.89991 | R26: ='Data-Cons'!#REF! -> #REF! | S26: =Q26/P26 -> 0.097039251 | T26: ='Data-Cons'!F44 -> 0 | U26: =P26/T26*100 -> #DIV/0!
N27: Q4&Q1 2022 | O27: Lst 3 Qtr 22 | P27: ='Data-Cons'!D43 -> 6149.1164 | Q27: ='Data-Cons'!E43 -> 579.44621 | R27: ='Data-Cons'!#REF! -> #REF! | S27: =Q27/P27 -> 0.094232435 | T27: ='Data-Cons'!F43 -> 0 | U27: =P27/T27*100 -> #DIV/0!
N29: Change | O29: Q2 | P29: =(P25-P24)/P24 -> 14.071826 | Q29: =(Q25-Q24)/Q24 -> #REF! | R29: =(R25-R24)/R24 -> #REF! | S29: =(S25-S24)/S24 -> #REF! | T29: =(T25-T24)/T24 -> #DIV/0! | U29: =(U25-U24)/U24 -> #DIV/0!
O30: Lst 3 Qtr | P30: =(P27-P26)/P26 -> 0.07340484 | Q30: =(Q27-Q26)/Q26 -> 0.042357096 | R30: =(R27-R26)/R26 -> #REF! | S30: =(S27-S26)/S26 -> -0.028924542 | T30: =(T27-T26)/T26 -> #DIV/0! | U30: =(U27-U26)/U26 -> #DIV/0!
B34: Sales Development | E34: Vol Chg | F34: Price | H34: Adj Op Mgn | I34: =I17 -> Q2 2021 | J34: =J17 -> Q2 2022 | K34: =K17 -> Lst 3 Qtr 21 | L34: =L17 -> Lst 3 Qtr 22
B35: Q2 2022 vs. Q2 2021 | E35: =T29 -> #DIV/0! | F35: =U29 -> #DIV/0! | H35: Sales | I35: =P24 -> 141.15652 | J35: =P25 -> 2127.4865 | K35: =P26 -> 5728.6088 | L35: =P27 -> 6149.1164
B36: Lst 3 Qtr 2022 vs. Lst 3 Qtr 2021 | E36: =T30 -> #DIV/0! | F36: =U30 -> #DIV/0! | H36: OP Profit | I36: =Q24 -> 170.1756 | J36: =Q25 -> #REF! | K36: =Q26 -> 555.89991 | L36: =Q27 -> 579.44621
H37: Op Mgn % | I37: =I36/I35 -> 1.2055809 | J37: =J36/J35 -> #REF! | K37: =K36/K35 -> 0.097039251 | L37: =L36/L35 -> 0.094232435
N40: SMFD Period | O40: Period | P40: Smfd Sales | Q40: Smfd Seg Prof | R40: Smfd Op Prof | S40: Op Mgn | T40: Volume | U40: ASP
N41: Q2 2021 | O41: Q2 2021 | P41: ='Data-Cons'!D24 -> 3717.272 | Q41: ='Data-Cons'!E24 -> 192.549 | R41: ='Data-Cons'!#REF! -> #REF! | S41: =R41/P41 -> #REF! | T41: ='Data-Cons'!F24 -> 0 | U41: =P41/T41*100 -> #DIV/0!
N42: Q2 2022 | O42: Q2 2022 | P42: ='Data-Cons'!D28 -> 3743.2 | Q42: ='Data-Cons'!E28 -> 293.6 | R42: ='Data-Cons'!#REF! -> #REF! | S42: =R42/P42 -> #REF! | T42: ='Data-Cons'!F28 -> 0 | U42: =P42/T42*100 -> #DIV/0!
N43: H1 2021 | O43: ='Data-Cons'!C35 -> Lst 3 Qtr 21 | P43: ='Data-Cons'!D35 -> 10746.099 | Q43: ='Data-Cons'!E35 -> 381.188 | R43: ='Data-Cons'!#REF! -> #REF! | S43: =R43/P43 -> #REF! | T43: ='Data-Cons'!F35 -> 0 | U43: =P43/T43*100 -> #DIV/0!
N44: H1 2022 | O44: ='Data-Cons'!C36 -> Lst 3 Qtr 22 | P44: ='Data-Cons'!D36 -> 11240.328 | Q44: ='Data-Cons'!E36 -> 1026.9 | R44: ='Data-Cons'!#REF! -> #REF! | S44: =R44/P44 -> #REF! | T44: ='Data-Cons'!F36 -> 0 | U44: =P44/T44*100 -> #DIV/0!
B51: Sales Development | E51: Vol Chg | F51: Price | H51: Adj Op Mgn | I51: =I17 -> Q2 2021 | J51: =J17 -> Q2 2022 | K51: =K17 -> Lst 3 Qtr 21 | L51: =L17 -> Lst 3 Qtr 22 | N51: Change | O51: Q2 | P51: =(P42-P41)/P41 -> 0.0069750075 | Q51: =(Q42-Q41)/Q41 -> 0.52480667 | R51: =(R42-R41)/R41 -> #REF! | S51: =(S42-S41)/S41 -> #REF! | T51: =(T42-T41)/T41 -> #DIV/0! | U51: =(U42-U41)/U41 -> #DIV/0!
B52: Q2 2022 vs. Q2 2021 | E52: =T51 -> #DIV/0! | F52: =U51 -> #DIV/0! | H52: Sales | I52: =P41 -> 3717.272 | J52: =P42 -> 3743.2 | K52: =P43 -> 10746.099 | L52: =P44 -> 11240.328 | O52: Lst 3 Qtr | P52: =(P44-P43)/P43 -> 0.04599148 | Q52: =(Q44-Q43)/Q43 -> 1.6939463 | R52: =(R44-R43)/R43 -> #REF! | S52: =(S44-S43)/S43 -> #REF! | T52: =(T44-T43)/T43 -> #DIV/0! | U52: =(U44-U43)/U43 -> #DIV/0!
B53: Lst 3 Qtr 2022 vs. Lst 3 Qtr 2021 | E53: =T52 -> #DIV/0! | F53: =U52 -> #DIV/0! | H53: OP Profit | I53: =Q41 -> 192.549 | J53: =Q42 -> 293.6 | K53: =Q43 -> 381.188 | L53: =Q44 -> 1026.9
H54: Op Mgn % | I54: =I53/I52 -> 0.051798469 | J54: =J53/J52 -> 0.078435563 | K54: =K53/K52 -> 0.035472221 | L54: =L53/L52 -> 0.091358544

Sheet Q2 2022 (HML)
B1: Smithfield Packaged Meats Comparison to Tyson (Prepared Foods) & Hormel (Refrigerated Foods)
B2: Dollars in Millions
N5: Tyson | O5: Period | P5: Tyson Sales | Q5: Tyson Op Prof | R5: Tyson Op Prof | S5: Op Mgn | T5: Volume | U5: ASP
N6: Q1 2021 | O6: Q2 2021 | P6: ='Data-Cons'!D5 -> 4038 | Q6: ='Data-Cons'!E5 -> 217 | R6: ='Data-Cons'!#REF! -> #REF! | S6: =Q6/P6 -> 0.053739475 | U6: =P6/T6*100 -> #DIV/0!
N7: Q1 2022 | O7: Q2 2022 | P7: ='Data-Cons'!D8 -> 4066 | Q7: ='Data-Cons'!E8 -> 211 | R7: ='Data-Cons'!#REF! -> #REF! | S7: =Q7/P7 -> 0.051893753 | U7: =P7/T7*100 -> #DIV/0!
N8: Q4&Q1 2021 | O8: ='Data-Cons'!C15 -> Lst 3 Qtr 21 | P8: ='Data-Cons'!D15 -> 8315 | Q8: ='Data-Cons'!E15 -> 700 | R8: ='Data-Cons'!#REF! -> #REF! | S8: =Q8/P8 -> 0.084185207 | T8: ='Data-Cons'!F15 -> 2670 | U8: =P8/T8*100 -> 311.42322
N9: Q4&Q1 2022 | O9: ='Data-Cons'!C16 -> Lst 3 Qtr 22 | P9: ='Data-Cons'!D16 -> 8792 | Q9: ='Data-Cons'!E16 -> 660 | R9: ='Data-Cons'!#REF! -> #REF! | S9: =Q9/P9 -> 0.075068244 | T9: ='Data-Cons'!F16 -> 2520 | U9: =P9/T9*100 -> 348.88889
N10: Change | O10: Q2 | P10: =(P7-P6)/P6 -> 0.0069341258 | Q10: =(Q7-Q6)/Q6 -> -0.02764977 | R10: =(R7-R6)/R6 -> #REF! | S10: =(S7-S6)/S6 -> -0.034345738 | T10: -0.085 | U10: 0.138
O11: Lst 3 Qtr | P11: =(P9-P8)/P8 -> 0.057366206 | Q11: =(Q9-Q8)/Q8 -> -0.057142857 | R11: =(R9-R8)/R8 -> #REF! | S11: =(S9-S8)/S8 -> -0.1082965 | T11: -0.055 | U11: 0.142
B12: Sales Development | E12: Vol Chg | F12: Price | H12: SP Mgn | I12: =O32 -> Q2 2021 | J12: =O33 -> Q2 2022 | K12: =O34 -> Lst 3 Qtr 21 | L12: =O35 -> Lst 3 Qtr 22
B13: Q2 2022 vs. Q2 2021 | E13: =T10 -> -0.085 | F13: =U10 -> 0.138 | H13: Sales | I13: =P6 -> 4038 | J13: =P7 -> 4066 | K13: =P8 -> 8315 | L13: =P9 -> 8792
B14: Lst 3 Qtr 2022 vs. Lst 3 Qtr 2021 | E14: =T11 -> -0.055 | F14: =U11 -> 0.142 | H14: Seg Prof | I14: =Q6 -> 217 | J14: =Q7 -> 211 | K14: =Q8 -> 700 | L14: =Q9 -> 660
H15: SP Mgn % | I15: =I14/I13 -> 0.053739475 | J15: =J14/J13 -> 0.051893753 | K15: =K14/K13 -> 0.084185207 | L15: =L14/L13 -> 0.075068244
N18: Hormel | O18: Period | P18: Hormel Sales | Q18: Hormel Op Prof | R18: Hormel Op Prof | S18: Op Mgn | T18: Volume | U18: ASP
N19: Q1 2021 | O19: Q2 2021 | P19: ='Data-Cons'!E45 -> 141.15652 | Q19: ='Data-Cons'!E46 -> 170.1756 | R19: ='Data-Cons'!#REF! -> #REF! | S19: =Q19/P19 -> 1.2055809 | T19: ='Data-Cons'!F46 -> 0 | U19: =P19/T19*100 -> #DIV/0!
N20: Q1 2022 | O20: Q2 2022 | P20: ='Data-Cons'!D45 -> 2127.4865 | Q20: ='Data-Cons'!#REF! -> #REF! | R20: ='Data-Cons'!#REF! -> #REF! | S20: =Q20/P20 -> #REF! | T20: ='Data-Cons'!F45 -> 0 | U20: =P20/T20*100 -> #DIV/0!
N21: Q4&Q1 2021 | O21: Lst 3 Qtr 21 | P21: ='Data-Cons'!D44 -> 5728.6088 | Q21: ='Data-Cons'!E44 -> 555.89991 | R21: ='Data-Cons'!#REF! -> #REF! | S21: =Q21/P21 -> 0.097039251 | T21: ='Data-Cons'!F44 -> 0 | U21: =P21/T21*100 -> #DIV/0!
N22: Q4&Q1 2022 | O22: Lst 3 Qtr 22 | P22: ='Data-Cons'!D43 -> 6149.1164 | Q22: ='Data-Cons'!E43 -> 579.44621 | R22: ='Data-Cons'!#REF! -> #REF! | S22: =Q22/P22 -> 0.094232435 | T22: ='Data-Cons'!F43 -> 0 | U22: =P22/T22*100 -> #DIV/0!
N23: Change | O23: Q2 | P23: =(P20-P19)/P19 -> 14.071826 | Q23: =(Q20-Q19)/Q19 -> #REF! | R23: =(R20-R19)/R19 -> #REF! | S23: =(S20-S19)/S19 -> #REF! | T23: =(T20-T19)/T19 -> #DIV/0! | U23: =(U20-U19)/U19 -> #DIV/0!
O24: Lst 3 Qtr | P24: =(P22-P21)/P21 -> 0.07340484 | Q24: =(Q22-Q21)/Q21 -> 0.042357096 | R24: =(R22-R21)/R21 -> #REF! | S24: =(S22-S21)/S21 -> -0.028924542 | T24: =(T22-T21)/T21 -> #DIV/0! | U24: =(U22-U21)/U21 -> #DIV/0!
B25: Sales Development | E25: Vol Chg | F25: Price | H25: SP Mgn | I25: =I12 -> Q2 2021 | J25: =J12 -> Q2 2022 | K25: =K12 -> Lst 3 Qtr 21 | L25: =L12 -> Lst 3 Qtr 22
B26: Q2 2022 vs. Q2 2021 | E26: =T23 -> #DIV/0! | F26: =U23 -> #DIV/0! | H26: Sales | I26: =P19 -> 141.15652 | J26: =P20 -> 2127.4865 | K26: =P21 -> 5728.6088 | L26: =P22 -> 6149.1164
B27: Lst 3 Qtr 2022 vs. Lst 3 Qtr 2021 | E27: =T24 -> #DIV/0! | F27: =U24 -> #DIV/0! | H27: Seg Prof | I27: =Q19 -> 170.1756 | J27: =Q20 -> #REF! | K27: =Q21 -> 555.89991 | L27: =Q22 -> 579.44621
H28: SP Mgn % | I28: =I27/I26 -> 1.2055809 | J28: =J27/J26 -> #REF! | K28: =K27/K26 -> 0.097039251 | L28: =L27/L26 -> 0.094232435
N31: SMFD Period | O31: Period | P31: Smfd Sales | Q31: Smfd Seg Prof | R31: Smfd Op Prof | S31: Op Mgn | T31: Volume | U31: ASP
N32: Q2 2021 | O32: Q2 2021 | P32: ='Data-Cons'!D24 -> 3717.272 | Q32: ='Data-Cons'!E24 -> 192.549 | R32: ='Data-Cons'!#REF! -> #REF! | S32: =R32/P32 -> #REF! | T32: ='Data-Cons'!F24 -> 0 | U32: =P32/T32*100 -> #DIV/0!
N33: Q2 2022 | O33: Q2 2022 | P33: ='Data-Cons'!D28 -> 3743.2 | Q33: ='Data-Cons'!E28 -> 293.6 | R33: ='Data-Cons'!#REF! -> #REF! | S33: =R33/P33 -> #REF! | T33: ='Data-Cons'!F28 -> 0 | U33: =P33/T33*100 -> #DIV/0!
N34: H1 2021 | O34: ='Data-Cons'!C35 -> Lst 3 Qtr 21 | P34: ='Data-Cons'!D35 -> 10746.099 | Q34: ='Data-Cons'!E35 -> 381.188 | R34: ='Data-Cons'!#REF! -> #REF! | S34: =R34/P34 -> #REF! | T34: ='Data-Cons'!F35 -> 0 | U34: =P34/T34*100 -> #DIV/0!
N35: H1 2022 | O35: ='Data-Cons'!C36 -> Lst 3 Qtr 22 | P35: ='Data-Cons'!D36 -> 11240.328 | Q35: ='Data-Cons'!E36 -> 1026.9 | R35: ='Data-Cons'!#REF! -> #REF! | S35: =R35/P35 -> #REF! | T35: ='Data-Cons'!F36 -> 0 | U35: =P35/T35*100 -> #DIV/0!
N36: Change | O36: Q2 | P36: =(P33-P32)/P32 -> 0.0069750075 | Q36: =(Q33-Q32)/Q32 -> 0.52480667 | R36: =(R33-R32)/R32 -> #REF! | S36: =(S33-S32)/S32 -> #REF! | T36: =(T33-T32)/T32 -> #DIV/0! | U36: =(U33-U32)/U32 -> #DIV/0!
O37: Lst 3 Qtr | P37: =(P35-P34)/P34 -> 0.04599148 | Q37: =(Q35-Q34)/Q34 -> 1.6939463 | R37: =(R35-R34)/R34 -> #REF! | S37: =(S35-S34)/S34 -> #REF! | T37: =(T35-T34)/T34 -> #DIV/0! | U37: =(U35-U34)/U34 -> #DIV/0!
B38: Sales Development | E38: Vol Chg | F38: Price | H38: SP Mgn | I38: =I12 -> Q2 2021 | J38: =J12 -> Q2 2022 | K38: =K12 -> Lst 3 Qtr 21 | L38: =L12 -> Lst 3 Qtr 22
B39: Q2 2022 vs. Q2 2021 | E39: =T36 -> #DIV/0! | F39: =U36 -> #DIV/0! | H39: Sales | I39: =P32 -> 3717.272 | J39: =P33 -> 3743.2 | K39: =P34 -> 10746.099 | L39: =P35 -> 11240.328
B40: Lst 3 Qtr 2022 vs. Lst 3 Qtr 2021 | E40: =T37 -> #DIV/0! | F40: =U37 -> #DIV/0! | H40: Seg Prof | I40: =Q32 -> 192.549 | J40: =Q33 -> 293.6 | K40: =Q34 -> 381.188 | L40: =Q35 -> 1026.9
H41: SP Mgn % | I41: =I40/I39 -> 0.051798469 | J41: =J40/J39 -> 0.078435563 | K41: =K40/K39 -> 0.035472221 | L41: =L40/L39 -> 0.091358544

Sheet Q2 2022
B1: Smithfield Packaged Meats Comparison to Tyson
B2: Tyson Results have been converted to Smithfield's Calendar
B3: Dollars in Millions
N6: Tyson | O6: Period | P6: Tyson Sales | Q6: Tyson Op Prof | R6: Tyson Op Prof | S6: Op Mgn | T6: Volume | U6: ASP
N7: Q1 2021 | O7: Q2 2021 | P7: ='Data-Cons'!D5 -> 4038 | Q7: ='Data-Cons'!E5 -> 217 | R7: ='Data-Cons'!#REF! -> #REF! | S7: =Q7/P7 -> 0.053739475 | U7: =P7/T7*100 -> #DIV/0!
N8: Q1 2022 | O8: Q2 2022 | P8: ='Data-Cons'!D8 -> 4066 | Q8: ='Data-Cons'!E8 -> 211 | R8: ='Data-Cons'!#REF! -> #REF! | S8: =Q8/P8 -> 0.051893753 | U8: =P8/T8*100 -> #DIV/0!
N9: Q4&Q1 2021 | O9: ='Data-Cons'!C15 -> Lst 3 Qtr 21 | P9: ='Data-Cons'!D15 -> 8315 | Q9: ='Data-Cons'!E15 -> 700 | R9: ='Data-Cons'!#REF! -> #REF! | S9: =Q9/P9 -> 0.084185207 | T9: ='Data-Cons'!F15 -> 2670 | U9: =P9/T9*100 -> 311.42322
N10: Q4&Q1 2022 | O10: ='Data-Cons'!C16 -> Lst 3 Qtr 22 | P10: ='Data-Cons'!D16 -> 8792 | Q10: ='Data-Cons'!E16 -> 660 | R10: ='Data-Cons'!#REF! -> #REF! | S10: =Q10/P10 -> 0.075068244 | T10: ='Data-Cons'!F16 -> 2520 | U10: =P10/T10*100 -> 348.88889
N12: Change | O12: Q2 | P12: =(P8-P7)/P7 -> 0.0069341258 | Q12: =(Q8-Q7)/Q7 -> -0.02764977 | R12: =(R8-R7)/R7 -> #REF! | S12: =(S8-S7)/S7 -> -0.034345738 | T12: -0.085 | U12: 0.138
O13: Lst 3 Qtr | P13: =(P10-P9)/P9 -> 0.057366206 | Q13: =(Q10-Q9)/Q9 -> -0.057142857 | R13: =(R10-R9)/R9 -> #REF! | S13: =(S10-S9)/S9 -> -0.1082965 | T13: -0.055 | U13: 0.142
B17: Sales Development | E17: Vol Chg | F17: Price | H17: Adj Op Mgn | I17: =O24 -> Q2 2021 | J17: =O25 -> Q2 2022 | K17: =O26 -> Lst 3 Qtr 21 | L17: =O27 -> Lst 3 Qtr 22
B18: Q2 2022 vs. Q2 2021 | E18: =T12 -> -0.085 | F18: =U12 -> 0.138 | H18: Sales | I18: =P7 -> 4038 | J18: =P8 -> 4066 | K18: =P9 -> 8315 | L18: =P10 -> 8792
B19: Lst 3 Qtr 2022 vs. Lst 3 Qtr 2021 | E19: =T13 -> -0.055 | F19: =U13 -> 0.142 | H19: OP Profit | I19: =Q7 -> 217 | J19: =Q8 -> 211 | K19: =Q9 -> 700 | L19: =Q10 -> 660
H20: Op Mgn % | I20: =I19/I18 -> 0.053739475 | J20: =J19/J18 -> 0.051893753 | K20: =K19/K18 -> 0.084185207 | L20: =L19/L18 -> 0.075068244
N23: SMFD Period | O23: Period | P23: Smfd Sales | Q23: Smfd Seg Prof | R23: Smfd Op Prof | S23: Op Mgn | T23: Volume | U23: ASP
N24: Q2 2021 | O24: Q2 2021 | P24: ='Data-Cons'!D24 -> 3717.272 | Q24: ='Data-Cons'!E24 -> 192.549 | R24: ='Data-Cons'!#REF! -> #REF! | S24: =R24/P24 -> #REF! | T24: ='Data-Cons'!F24 -> 0 | U24: =P24/T24*100 -> #DIV/0!
N25: Q2 2022 | O25: Q2 2022 | P25: ='Data-Cons'!D28 -> 3743.2 | Q25: ='Data-Cons'!E28 -> 293.6 | R25: ='Data-Cons'!#REF! -> #REF! | S25: =R25/P25 -> #REF! | T25: ='Data-Cons'!F28 -> 0 | U25: =P25/T25*100 -> #DIV/0!
N26: H1 2021 | O26: ='Data-Cons'!C35 -> Lst 3 Qtr 21 | P26: ='Data-Cons'!D35 -> 10746.099 | Q26: ='Data-Cons'!E35 -> 381.188 | R26: ='Data-Cons'!#REF! -> #REF! | S26: =R26/P26 -> #REF! | T26: ='Data-Cons'!F35 -> 0 | U26: =P26/T26*100 -> #DIV/0!
N27: H1 2022 | O27: ='Data-Cons'!C36 -> Lst 3 Qtr 22 | P27: ='Data-Cons'!D36 -> 11240.328 | Q27: ='Data-Cons'!E36 -> 1026.9 | R27: ='Data-Cons'!#REF! -> #REF! | S27: =R27/P27 -> #REF! | T27: ='Data-Cons'!F36 -> 0 | U27: =P27/T27*100 -> #DIV/0!
B34: Sales Development | E34: Vol Chg | F34: Price | H34: Adj Op Mgn | I34: =I17 -> Q2 2021 | J34: =J17 -> Q2 2022 | K34: =K17 -> Lst 3 Qtr 21 | L34: =L17 -> Lst 3 Qtr 22 | N34: Change | O34: Q2 | P34: =(P25-P24)/P24 -> 0.0069750075 | Q34: =(Q25-Q24)/Q24 -> 0.52480667 | R34: =(R25-R24)/R24 -> #REF! | S34: =(S25-S24)/S24 -> #REF! | T34: =(T25-T24)/T24 -> #DIV/0! | U34: =(U25-U24)/U24 -> #DIV/0!
B35: Q2 2022 vs. Q2 2021 | E35: =T34 -> #DIV/0! | F35: =U34 -> #DIV/0! | H35: Sales | I35: =P24 -> 3717.272 | J35: =P25 -> 3743.2 | K35: =P26 -> 10746.099 | L35: =P27 -> 11240.328 | O35: Lst 3 Qtr | P35: =(P27-P26)/P26 -> 0.04599148 | Q35: =(Q27-Q26)/Q26 -> 1.6939463 | R35: =(R27-R26)/R26 -> #REF! | S35: =(S27-S26)/S26 -> #REF! | T35: =(T27-T26)/T26 -> #DIV/0! | U35: =(U27-U26)/U26 -> #DIV/0!
B36: Lst 3 Qtr 2022 vs. Lst 3 Qtr 2021 | E36: =T35 -> #DIV/0! | F36: =U35 -> #DIV/0! | H36: OP Profit | I36: =R24 -> #REF! | J36: =R25 -> #REF! | K36: =R26 -> #REF! | L36: =R27 -> #REF!
H37: Op Mgn % | I37: =I36/I35 -> #REF! | J37: =J36/J35 -> #REF! | K37: =K36/K35 -> #REF! | L37: =L36/L35 -> #REF!

Sheet Q1 2022
B1: Smithfield Packaged Meats Comparison to Tyson
B2: Tyson Results have been converted to Smithfield's Calendar
B3: Dollars in Millions
P5: Tyson
O6: Period | P6: Tyson Sales | Q6: Tyson Operating Profit | R6: Tyson Operating Profit | S6: Op Mgn
N7: 2Q21 | O7: Q1 2021 | P7: 2164 | Q7: 217 | R7: 217 | S7: =Q7/P7 -> 0.10027726
N8: 2Q22 | O8: Q1 2022 | P8: 2393 | Q8: 263 | R8: 263 | S8: =Q8/P8 -> 0.10990389
N9: 1H21 | O9: Q4&Q1 2021 | P9: 4277 | Q9: 483 | R9: 483 | S9: =Q9/P9 -> 0.11292962
N10: 1H22 | O10: Q4&Q1 2022 | P10: 4726 | Q10: 449 | R10: 449 | S10: =Q10/P10 -> 0.095006348
N12: Change | O12: Q1 | P12: =(P8-P7)/P7 -> 0.10582255 | Q12: =(Q8-Q7)/Q7 -> 0.21198157 | R12: =(R8-R7)/R7 -> 0.21198157
O13: H1 | P13: =(P10-P9)/P9 -> 0.10498013 | Q13: =(Q10-Q9)/Q9 -> -0.070393375 | R13: =(R10-R9)/R9 -> -0.070393375
B17: Sales Development | E17: Vol Chg | F17: Price | H17: Adj Op Mgn | I17: =O26 -> Q1 2021 | J17: =O27 -> Q1 2022 | K17: =O28 -> Q4&Q1 2021 | L17: =O29 -> Q4&Q1 2022
B18: Q1 2022 vs. Q1 2021 | E18: -0.053 | F18: 0.159 | H18: Sales | I18: =P7 -> 2164 | J18: =P8 -> 2393 | K18: =P9 -> 4277 | L18: =P10 -> 4726
B19: Q4 & Q1 2022 vs. Q4 & Q1 2021 | E19: -0.04 | F19: 0.145 | H19: OP Profit | I19: =R7 -> 217 | J19: =R8 -> 263 | K19: =R9 -> 483 | L19: =R10 -> 449
H20: Op Mgn % | I20: =I19/I18 -> 0.10027726 | J20: =J19/J18 -> 0.10990389 | K20: =K19/K18 -> 0.11292962 | L20: =L19/L18 -> 0.095006348
P22: Smithfield
N23: SMFD Period | O23: Period | P23: Smithfield Sales | Q23: Smithfield Seg Profit | R23: Smithfield Operating Profit | S23: Op Mgn | T23: Volume | U23: ASP
N24: Q4 2020 | P24: 2171.7 | Q24: 175.8 | R24: 162.5 | S24: =R24/P24 -> 0.074826173 | T24: 977.5 | U24: =P24/T24*100 -> 222.1688
N25: Q4 2021 | P25: 2565.3 | Q25: 358.4 | R25: 359.2 | S25: =R25/P25 -> 0.14002261 | T25: 945.9 | U25: =P25/T25*100 -> 271.20203
N26: Q1 2021 | O26: Q1 2021 | P26: 1916.5 | Q26: 192 | R26: 188.6 | S26: =R26/P26 -> 0.098408557 | T26: 812.4 | U26: =P26/T26*100 -> 235.90596
N27: Q1 2022 | O27: Q1 2022 | P27: 2232.8 | Q27: 300.2 | R27: 300.6 | S27: =R27/P27 -> 0.13462917 | T27: 784.1 | U27: =P27/T27*100 -> 284.7596
N28: Q42020 + Q12021 | O28: Q4&Q1 2021 | P28: =P24+P26 -> 4088.2 | Q28: =Q24+Q26 -> 367.8 | R28: =R24+R26 -> 351.1 | S28: =R28/P28 -> 0.085881317 | T28: =T24+T26 -> 1789.9 | U28: =P28/T28*100 -> 228.40382
N29: Q42021 + Q12022 | O29: Q4&Q1 2022 | P29: =P25+P27 -> 4798.1 | Q29: =Q25+Q27 -> 658.6 | R29: =R25+R27 -> 659.8 | S29: =R29/P29 -> 0.13751277 | T29: =T25+T27 -> 1730 | U29: =P29/T29*100 -> 277.34682
N30: Change | O30: Q1 | P30: =(P27-P26)/P26 -> 0.16504044 | Q30: =(Q27-Q26)/Q26 -> 0.56354167 | R30: =(R27-R26)/R26 -> 0.59384942 | S30: =(S27-S26)/S26 -> 0.3680636 | T30: =(T27-T26)/T26 -> -0.034835057 | U30: =(U27-U26)/U26 -> 0.20708947
O31: H1 | P31: =(P29-P28)/P28 -> 0.1736461 | Q31: =(Q29-Q28)/Q28 -> 0.79064709 | R31: =(R29-R28)/R28 -> 0.87923668 | S31: =(S29-S28)/S28 -> 0.60119535 | T31: =(T29-T28)/T28 -> -0.033465557 | U31: =(U29-U28)/U28 -> 0.21428275
B34: Sales Development | E34: Vol Chg | F34: Price | H34: Adj Op Mgn | I34: =O26 -> Q1 2021 | J34: =O27 -> Q1 2022 | K34: =O28 -> Q4&Q1 2021 | L34: =O29 -> Q4&Q1 2022
B35: Q1 2022 vs. Q1 2021 | E35: =T30 -> -0.034835057 | F35: =U30 -> 0.20708947 | H35: Sales | I35: =P26 -> 1916.5 | J35: =P27 -> 2232.8 | K35: =P28 -> 4088.2 | L35: =P29 -> 4798.1
B36: Q4 & Q1 2022 vs. Q4 & Q1 2021 | E36: =T31 -> -0.033465557 | F36: =U31 -> 0.21428275 | H36: OP Profit | I36: =R26 -> 188.6 | J36: =R27 -> 300.6 | K36: =R28 -> 351.1 | L36: =R29 -> 659.8
H37: Op Mgn % | I37: =I36/I35 -> 0.098408557 | J37: =J36/J35 -> 0.13462917 | K37: =K36/K35 -> 0.085881317 | L37: =L36/L35 -> 0.13751277

Sheet Special SGA
A1: US Packaged Meats
A3: SGA Summary | B3: Q1 2022 | C3: Q2 2022 | D3: Q3 2022 | E3: Q4 2022 | F3: Tot 2022 | H3: Q4+Q1 | I3: Q2+Q3 | J3: Chg | K3: % Chg
A4: 2022 Fcst | B4: =B26 -> 12.358432 | C4: =C26 -> 14.177451 | D4: =D26 -> 14.395026 | E4: =E26 -> 10.799929 | F4: =F26 -> 12.748705 | H4: =H26 -> 11.480839 | I4: =I26 -> 14.286117 | J4: =H4-I4 -> -2.8052776 | K4: =J4/H4 -> -0.2443443
A5: 2021 | B5: =B45 -> 11.440434 | C5: =C45 -> 12.679429 | D5: =D45 -> 13.865446 | E5: =E45 -> 10.503572 | F5: =F45 -> 11.969835 | H5: =H45 -> 10.936437 | I5: =I45 -> 13.270389 | J5: =H5-I5 -> -2.3339528 | K5: =J5/H5 -> -0.21341072
A6: 2020 | B6: =B64 -> 13.654888 | C6: =C64 -> 15.412848 | D6: =D64 -> 15.636632 | E6: =E64 -> 11.641133 | F6: =F64 -> 13.796637 | H6: =H64 -> 12.546613 | I6: =I64 -> 15.523142 | J6: =H6-I6 -> -2.9765283 | K6: =J6/H6 -> -0.23723759
A7: 2019 | B7: =B83 -> 15.355371 | C7: =C83 -> 15.615764 | D7: =D83 -> 16.170418 | E7: =E83 -> 12.715636 | F7: =F83 -> 14.791661 | H7: =H83 -> 13.861431 | I7: =I83 -> 15.882144 | J7: =H7-I7 -> -2.0207129 | K7: =J7/H7 -> -0.14577954
A8: 4 Year Avg | B8: =AVERAGE(B4:B7) -> 13.202281 | C8: =AVERAGE(C4:C7) -> 14.471373 | D8: =AVERAGE(D4:D7) -> 15.01688 | E8: =AVERAGE(E4:E7) -> 11.415068 | F8: =AVERAGE(F4:F7) -> 13.326709 | H8: =AVERAGE(H4:H7) -> 12.20633 | I8: =AVERAGE(I4:I7) -> 14.740448 | J8: =H8-I8 -> -2.5341179 | K8: =J8/H8 -> -0.20760687
B10: Actuals | C10: Budget | D10: Budget | E10: Budget | F10: FCST | H10: Quarterly Comparison
B11: Q1 2022 | C11: Q2 2022 | D11: Q3 2022 | E11: Q4 2022 | F11: Tot 2022 | H11: Q4+Q1 | I11: Q2+Q3 | J11: Chg | K11: % Chg
A12: Dollars
A13: Sales Total | B13: 2232.8179 | C13: 2089.5027 | D13: 2089.0248 | E13: 2532.3872 | F13: =SUM(B13:E13) -> 8943.7327 | H13: =B13+E13 -> 4765.2052 | I13: =SUM(C13:D13) -> 4178.5275 | J13: =H13-I13 -> 586.67762 | K13: =J13/H13 -> 0.12311697
A14: SEGMENT PROFIT | B14: 300.15571 | C14: 206.79038 | D14: 170.47726 | E14: 300.52054 | F14: =SUM(B14:E14) -> 977.94388 | H14: =B14+E14 -> 600.67625 | I14: =SUM(C14:D14) -> 377.26764 | J14: =H14-I14 -> 223.40861 | K14: =J14/H14 -> 0.37192849
A15: Gross Margin % | B15: 0.17782995 | C15: 0.14923522 | D15: 0.13254415 | E15: 0.16177135 | F15: =(F19-F20-F21-F22)/F19 -> 0.1560249 | H15: =(H19-H20-H21-H22)/H19 -> 0.16929588 | I15: =(I19-I20-I21-I22)/I19 -> 0.14089064 | J15: =H15-I15 -> 0.028405244 | K15: =J15/H15 -> 0.16778461
A16: Segment Margin % | B16: 0.1344291 | C16: 0.09896631 | D16: 0.081606145 | E16: 0.11867085 | F16: =F14/F13 -> 0.10934404 | H16: =H14/H13 -> 0.12605465 | I16: =I14/I13 -> 0.090287221 | J16: =H16-I16 -> 0.035767425 | K16: =J16/H16 -> 0.28374539
A17: Per cwt
A18: Sales Vol (lbs mm) | B18: 784.13021 | C18: 740.87387 | D18: 739.21885 | E18: 1010.6285 | F18: =SUM(B18:E18) -> 3274.8515 | H18: =B18+E18 -> 1794.7587 | I18: =C18+D18 -> 1480.0927 | J18: =H18-I18 -> 314.66602 | K18: =J18/H18 -> 0.17532497
A19: Sales | B19: 284.75091 | C19: 282.03218 | D19: 282.59896 | E19: 250.57547 | F19: =((B19/100*$B$18)+(C19/100*$C$18)+(D19/100*$D$18)+(E19/100*$E$18))/$F$18*100 -> 273.10346 | H19: =((B19/100*B18)+(E19/100*E18))/(H18)*100 -> 265.50673 | I19: =((C19/100*C18)+(D19/100*D18))/(I18)*100 -> 282.31526 | J19: =H19-I19 -> -16.80853 | K19: =J19/H19 -> -0.063307362
A20: Raw Material | B20: 163.35361 | C20: 166.64376 | D20: 170.87562 | E20: 152.50212 | F20: =((B20/100*$B$18)+(C20/100*$C$18)+(D20/100*$D$18)+(E20/100*$E$18))/$F$18*100 -> 162.44706 | H20: =((B20/100*B18)+(E20/100*E18))/(H18)*100 -> 157.24314 | I20: =((C20/100*C18)+(D20/100*D18))/(I18)*100 -> 168.75732 | J20: =H20-I20 -> -11.514186 | K20: =J20/H20 -> -0.073225364
A21: MFG Expense | B21: 50.947541 | C21: 55.626054 | D21: 56.560711 | E21: 40.709998 | F21: =((B21/100*$B$18)+(C21/100*$C$18)+(D21/100*$D$18)+(E21/100*$E$18))/$F$18*100 -> 50.11367 | H21: =((B21/100*B18)+(E21/100*E18))/(H18)*100 -> 45.182781 | I21: =((C21/100*C18)+(D21/100*D18))/(I18)*100 -> 56.09286 | J21: =H21-I21 -> -10.910079 | K21: =J21/H21 -> -0.24146542
A22: Distribution | B22: 19.81252 | C22: 17.673236 | D22: 17.70579 | E22: 16.827421 | F22: =((B22/100*$B$18)+(C22/100*$C$18)+(D22/100*$D$18)+(E22/100*$E$18))/$F$18*100 -> 17.931793 | H22: =((B22/100*B18)+(E22/100*E18))/(H18)*100 -> 18.131611 | I22: =((C22/100*C18)+(D22/100*D18))/(I18)*100 -> 17.689495 | J22: =H22-I22 -> 0.44211603 | K22: =J22/H22 -> 0.024383715
A23: Mktng & Adv | B23: 2.519655 | C23: 3.3282692 | D23: 3.5224043 | E23: 2.6985461 | F23: =((B23/100*$B$18)+(C23/100*$C$18)+(D23/100*$D$18)+(E23/100*$E$18))/$F$18*100 -> 2.9841416 | H23: =((B23/100*B18)+(E23/100*E18))/(H18)*100 -> 2.6203886 | I23: =((C23/100*C18)+(D23/100*D18))/(I18)*100 -> 3.4252282 | J23: =H23-I23 -> -0.80483967 | K23: =J23/H23 -> -0.30714516
A24: Selling | B24: 4.7300349 | C24: 4.7865851 | D24: 4.7977345 | E24: 3.6222423 | F24: =((B24/100*$B$18)+(C24/100*$C$18)+(D24/100*$D$18)+(E24/100*$E$18))/$F$18*100 -> 4.4162419 | H24: =((B24/100*B18)+(E24/100*E18))/(H18)*100 -> 4.106237 | I24: =((C24/100*C18)+(D24/100*D18))/(I18)*100 -> 4.7921536 | J24: =H24-I24 -> -0.68591661 | K24: =J24/H24 -> -0.16704263
A25: Admin | B25: 5.1087426 | C25: 6.0625966 | D25: 6.0748871 | E25: 4.4791405 | F25: =((B25/100*$B$18)+(C25/100*$C$18)+(D25/100*$D$18)+(E25/100*$E$18))/$F$18*100 -> 5.348321 | H25: =((B25/100*B18)+(E25/100*E18))/(H18)*100 -> 4.7542137 | I25: =((C25/100*C18)+(D25/100*D18))/(I18)*100 -> 6.068735 | J25: =H25-I25 -> -1.3145213 | K25: =J25/H25 -> -0.27649605
A26: Total SGA Subtotal | B26: =SUM(B23:B25) -> 12.358432 | C26: =SUM(C23:C25) -> 14.177451 | D26: =SUM(D23:D25) -> 14.395026 | E26: =SUM(E23:E25) -> 10.799929 | F26: =((B26/100*$B$18)+(C26/100*$C$18)+(D26/100*$D$18)+(E26/100*$E$18))/$F$18*100 -> 12.748705 | H26: =((B26/100*B18)+(E26/100*E18))/(H18)*100 -> 11.480839 | I26: =((C26/100*C18)+(D26/100*D18))/(I18)*100 -> 14.286117 | J26: =H26-I26 -> -2.8052776 | K26: =J26/H26 -> -0.2443443
A27: Segment Profits | B27: 38.278809 | C27: 27.911685 | D27: 23.061812 | E27: 29.736004 | F27: =((B27/100*$B$18)+(C27/100*$C$18)+(D27/100*$D$18)+(E27/100*$E$18))/$F$18*100 -> 29.862236 | H27: =((B27/100*B18)+(E27/100*E18))/(H18)*100 -> 33.468356 | I27: =((C27/100*C18)+(D27/100*D18))/(I18)*100 -> 25.48946 | J27: =H27-I27 -> 7.9788963 | K27: =J27/H27 -> 0.2384012
B29: 2021 Actuals | H29: Quarterly Comparison
B30: Q1 2021 | C30: Q2 2021 | D30: Q3 2021 | E30: Q4 2021 | F30: Tot 2021 | H30: Q4+Q1 | I30: Q2+Q3 | J30: Chg | K30: % Chg
A31: Dollars
A32: Sales Total | B32: 1916.5269 | C32: 1956.5455 | D32: 2077.0785 | E32: 2564.4528 | F32: 8514.6037 | H32: =B32+E32 -> 4480.9797 | I32: =SUM(C32:D32) -> 4033.624 | J32: =H32-I32 -> 447.35577 | K32: =J32/H32 -> 0.099834365
A33: SEGMENT PROFIT | B33: 191.96106 | C33: 163.54863 | D33: 164.59376 | E33: 358.41769 | F33: 878.52113 | H33: =B33+E33 -> 550.37875 | I33: =SUM(C33:D33) -> 328.14238 | J33: =H33-I33 -> 222.23637 | K33: =J33/H33 -> 0.40378806
A34: Gross Margin % | B34: 0.14865614 | C34: 0.12901724 | D34: 0.12571405 | E34: 0.17850654 | F34: 0.14753724 | H34: =(H38-H39-H40-H41)/H38 -> 0.16573944 | I34: =(I38-I39-I40-I41)/I38 -> 0.12731629 | J34: =H34-I34 -> 0.038423151 | K34: =J34/H34 -> 0.23182865
A35: Segment Margin % | B35: 0.1001609 | C35: 0.083590505 | D35: 0.079242916 | E35: 0.13976381 | F35: 0.10317816 | H35: =H33/H32 -> 0.12282554 | I35: =I33/I32 -> 0.081351753 | J35: =H35-I35 -> 0.041473786 | K35: =J35/H35 -> 0.33766419
A36: Per cwt
A37: Sales Vol (lbs mm) | B37: 812.403 | C37: 700.97386 | D37: 696.14919 | E37: 945.90589 | F37: 3155.432 | H37: =B37+E37 -> 1758.3089 | I37: =C37+D37 -> 1397.1231 | J37: =H37-I37 -> 361.18584 | K37: =J37/H37 -> 0.2054166
A38: Sales | B38: 235.9084 | C38: 279.11818 | D38: 298.36686 | E38: 271.11078 | F38: 269.83956 | H38: =((B38/100*B37)+(E38/100*E37))/(H37)*100 -> 254.84599 | I38: =((C38/100*C37)+(D38/100*D37))/(I37)*100 -> 288.70928 | J38: =H38-I38 -> -33.863292 | K38: =J38/H38 -> -0.13287747
A39: Raw Material | B39: 136.72446 | C39: 180.91526 | D39: 190.30018 | E39: 151.98558 | F39: 162.93604 | H39: =((B39/100*B37)+(E39/100*E37))/(H37)*100 -> 144.93439 | I39: =((C39/100*C37)+(D39/100*D37))/(I37)*100 -> 185.59151 | J39: =H39-I39 -> -40.657128 | K39: =J39/H39 -> -0.28052092
A40: MFG Expense | B40: 47.118223 | C40: 44.674819 | D40: 51.025583 | E40: 51.726473 | F40: 48.818882 | H40: =((B40/100*B37)+(E40/100*E37))/(H37)*100 -> 49.597293 | I40: =((C40/100*C37)+(D40/100*D37))/(I37)*100 -> 47.839236 | J40: =H40-I40 -> 1.7580568 | K40: =J40/H40 -> 0.035446629
A41: Distribution | B41: 16.996484 | C41: 17.517048 | D41: 19.53219 | E41: 19.003678 | F41: 18.27325 | H41: =((B41/100*B37)+(E41/100*E37))/(H37)*100 -> 18.076281 | I41: =((C41/100*C37)+(D41/100*D37))/(I37)*100 -> 18.52114 | J41: =H41-I41 -> -0.44485827 | K41: =J41/H41 -> -0.024610054
A42: Mktng & Adv | B42: 2.4901375 | C42: 3.2848538 | D42: 4.0231466 | E42: 3.204666 | F42: 3.2190885 | H42: =((B42/100*B37)+(E42/100*E37))/(H37)*100 -> 2.8745277 | I42: =((C42/100*C37)+(D42/100*D37))/(I37)*100 -> 3.6527254 | J42: =H42-I42 -> -0.77819772 | K42: =J42/H42 -> -0.27072194
A43: Selling | B43: 4.4586488 | C43: 4.7214011 | D43: 4.7576867 | E43: 2.6844745 | F43: 4.0511469 | H43: =((B43/100*B37)+(E43/100*E37))/(H37)*100 -> 3.5042079 | I43: =((C43/100*C37)+(D43/100*D37))/(I37)*100 -> 4.7394812 | J43: =H43-I43 -> -1.2352733 | K43: =J43/H43 -> -0.35251142
...

Sheet SGA
B2: 44583 | C2: 44614 | D2: 44642 | E2: 44673 | F2: 44703 | G2: 44734 | H2: 44764 | I2: 44795 | J2: 44826 | K2: 44856 | L2: 44887 | M2: 44917 | N2: Q1 FY22 | O2: Q2 FY22 | P2: Q3 FY22 | Q2: Q4 FY22 | R2: FY22
A3: Volume:
A4: Sales Vol (lbs mm) | B4: 205.19181 | C4: 223.04328 | D4: 355.89513 | E4: 0 | F4: 0 | G4: 0 | H4: 0 | I4: 0 | J4: 0 | K4: 0 | L4: 0 | M4: 0 | N4: 784.13021 | O4: 0 | P4: 0 | Q4: 0 | R4: 784.13021
A5: Sales Total | B5: 583.59893 | C5: 648.44914 | D5: 1000.7699 | E5: 0 | F5: 0 | G5: 0 | H5: 0 | I5: 0 | J5: 0 | K5: 0 | L5: 0 | M5: 0 | N5: 2232.8179 | O5: 0 | P5: 0 | Q5: 0 | R5: 2232.8179
A6: SEGMENT PROFIT | B6: 88.08969 | C6: 84.887359 | D6: 127.17866 | E6: 0 | F6: 0 | G6: 0 | H6: 0 | I6: 0 | J6: 0 | K6: 0 | L6: 0 | M6: 0 | N6: 300.15571 | O6: 0 | P6: 0 | Q6: 0 | R6: 300.15571
A7: Gross Margin % | B7: 0.20228857 | C7: 0.17535043 | D7: 0.16517352 | E7: 0 | F7: 0 | G7: 0 | H7: 0 | I7: 0 | J7: 0 | K7: 0 | L7: 0 | M7: 0 | N7: 0.17782995 | O7: 0 | P7: 0 | Q7: 0 | R7: 0.17782995
A8: Segment Margin % | B8: 0.15094217 | C8: 0.13090828 | D8: 0.12708082 | E8: 0 | F8: 0 | G8: 0 | H8: 0 | I8: 0 | J8: 0 | K8: 0 | L8: 0 | M8: 0 | N8: 0.1344291 | O8: 0 | P8: 0 | Q8: 0 | R8: 0.1344291
A9: Per cwt
A10: Sales | B10: 284.41629 | C10: 290.72794 | D10: 281.19797 | E10: 0 | F10: 0 | G10: 0 | H10: 0 | I10: 0 | J10: 0 | K10: 0 | L10: 0 | M10: 0 | N10: 284.75091 | O10: 0 | P10: 0 | Q10: 0 | R10: 284.75091
A11: Raw Material | B11: 154.48795 | C11: 168.13046 | D11: 165.47141 | E11: 0 | F11: 0 | G11: 0 | H11: 0 | I11: 0 | J11: 0 | K11: 0 | L11: 0 | M11: 0 | N11: 163.35361 | O11: 0 | P11: 0 | Q11: 0 | R11: 163.35361
A12: MFG Expense | B12: 50.904223 | C12: 50.586089 | D12: 51.199042 | E12: 0 | F12: 0 | G12: 0 | H12: 0 | I12: 0 | J12: 0 | K12: 0 | L12: 0 | M12: 0 | N12: 50.947541 | O12: 0 | P12: 0 | Q12: 0 | R12: 50.947541
A13: Distribution | B13: 21.489957 | C13: 21.032125 | D13: 18.081052 | E13: 0 | F13: 0 | G13: 0 | H13: 0 | I13: 0 | J13: 0 | K13: 0 | L13: 0 | M13: 0 | N13: 19.81252 | O13: 0 | P13: 0 | Q13: 0 | R13: 19.81252
A14: Mktng & Adv | B14: 3.3324246 | C14: 3.1529863 | D14: 1.6541361 | E14: 0 | F14: 0 | G14: 0 | H14: 0 | I14: 0 | J14: 0 | K14: 0 | L14: 0 | M14: 0 | N14: 2.519655 | O14: 0 | P14: 0 | Q14: 0 | R14: 2.519655
A15: Selling | B15: 5.6113085 | C15: 4.7695277 | D15: 4.197185 | E15: 0 | F15: 0 | G15: 0 | H15: 0 | I15: 0 | J15: 0 | K15: 0 | L15: 0 | M15: 0 | N15: 4.7300349 | O15: 0 | P15: 0 | Q15: 0 | R15: 4.7300349
A16: Admin | B16: 5.6600198 | C16: 4.998061 | D16: 4.8602683 | E16: 0 | F16: 0 | G16: 0 | H16: 0 | I16: 0 | J16: 0 | K16: 0 | L16: 0 | M16: 0 | N16: 5.1087426 | O16: 0 | P16: 0 | Q16: 0 | R16: 5.1087426
A17: Segment Profits | B17: 42.930413 | C17: 38.058693 | D17: 35.734869 | E17: 0 | F17: 0 | G17: 0 | H17: 0 | I17: 0 | J17: 0 | K17: 0 | L17: 0 | M17: 0 | N17: 38.278809 | O17: 0 | P17: 0 | Q17: 0 | R17: 38.278809
B20: 44582 | C20: 44613 | D20: 44641 | E20: 44672 | F20: 44702 | G20: 44733 | H20: 44763 | I20: 44794 | J20: 44825 | K20: 44855 | L20: 44886 | M20: 44916 | N20: Q1 FY21 | O20: Q2 FY21 | P20: Q3 FY21 | Q20: Q4 FY21 | R20: FY21
A21: Volume:
A22: Sales Vol (lbs mm) | B22: 206.85943 | C22: 232.7428 | D22: 372.80078 | E22: 213.00193 | F22: 215.13477 | G22: 272.83717 | H22: 206.46574 | I22: 212.21098 | J22: 277.47247 | K22: 274.65699 | L22: 328.50154 | M22: 342.74736 | N22: 812.403 | O22: 700.97386 | P22: 696.14919 | Q22: 945.90589 | R22: 3155.432
A23: Sales Total | B23: 498.57132 | C23: 548.79806 | D23: 869.15753 | E23: 577.98372 | F23: 607.90166 | G23: 770.66012 | H23: 600.53221 | I23: 639.39825 | J23: 837.14803 | K23: 774.26736 | L23: 866.40985 | M23: 923.77562 | N23: 1916.5269 | O23: 1956.5455 | P23: 2077.0785 | Q23: 2564.4528 | R23: 8514.6037
A24: SEGMENT PROFIT | B24: 49.979341 | C24: 58.92079 | D24: 83.060932 | E24: 45.519805 | F24: 43.259946 | G24: 74.768875 | H24: 51.85743 | I24: 31.929195 | J24: 80.80713 | K24: 96.915435 | L24: 112.67586 | M24: 148.8264 | N24: 191.96106 | O24: 163.54863 | P24: 164.59376 | Q24: 358.41769 | R24: 878.52113
A25: Gross Margin % | B25: 0.15947416 | C25: 0.16278214 | D25: 0.13353129 | E25: 0.13166731 | F25: 0.12346728 | G25: 0.13140758 | H25: 0.13524381 | I25: 0.099599743 | J25: 0.13882346 | K25: 0.16646267 | L25: 0.16364422 | M25: 0.20254055 | N25: 0.14865614 | O25: 0.12901724 | P25: 0.12571405 | Q25: 0.17850654 | R25: 0.14753724
A26: Segment Margin % | B26: 0.10024512 | C26: 0.10736334 | D26: 0.095564876 | E26: 0.078756206 | F26: 0.071162738 | G26: 0.097019261 | H26: 0.086352454 | I26: 0.04993632 | J26: 0.096526693 | K26: 0.1251705 | L26: 0.13004914 | M26: 0.16110665 | N26: 0.1001609 | O26: 0.083590505 | P26: 0.079242916 | Q26: 0.13976381 | R26: 0.10317816
A27: Per cwt
A28: Sales | B28: 241.01939 | C28: 235.79594 | D28: 233.14263 | E28: 271.3514 | F28: 282.56783 | G28: 282.46156 | H28: 290.86288 | I28: 301.3031 | J28: 301.70489 | K28: 281.90339 | L28: 263.74605 | M28: 269.52086 | N28: 235.9084 | O28: 279.11818 | P28: 298.36686 | Q28: 271.11078 | R28: 269.83956
A29: Raw Material | B29: 134.10409 | C29: 134.41965 | D29: 139.61736 | E29: 158.86399 | F29: 205.37747 | G29: 178.84182 | H29: 183.54899 | I29: 196.11083 | J29: 190.87972 | K29: 164.41994 | L29: 149.12057 | M29: 144.76736 | N29: 136.72446 | O29: 180.91526 | P29: 190.30018 | Q29: 151.98558 | R29: 162.93604
A30: MFG Expense | B30: 50.126791 | C30: 45.84198 | D30: 46.2456 | E30: 58.63893 | F30: 24.857015 | G30: 49.399675 | H30: 47.875847 | I30: 55.508244 | J30: 49.940945 | K30: 50.573014 | L30: 52.407785 | M30: 51.99779 | N30: 47.118223 | O30: 44.674819 | P30: 51.025583 | Q30: 51.726473 | R30: 48.818882
A31: Distribution | B31: 18.352143 | C31: 17.150938 | D31: 16.14783 | E31: 18.120379 | F31: 17.445463 | G31: 17.102476 | H31: 20.100642 | I31: 19.674315 | J31: 19.000512 | K31: 19.984038 | L31: 19.057175 | M31: 18.166804 | N31: 16.996484 | O31: 17.517048 | P31: 19.53219 | Q31: 19.003678 | R31: 18.27325
A32: Mktng & Adv | B32: 2.7541365 | C32: 2.9058063 | D32: 2.0841442 | E32: 3.6086517 | F32: 4.1650589 | G32: 2.3380169 | H32: 4.6250088 | I32: 4.9085572 | J32: 2.8981421 | K32: 4.1933166 | L32: 2.4382176 | M32: 3.1470134 | N32: 2.4901375 | O32: 3.2848538 | P32: 4.0231466 | Q32: 3.204666 | R32: 3.2190885
A33: Selling | B33: 5.4575568 | C33: 4.6465814 | D33: 3.7870474 | E33: 5.1188422 | F33: 4.8789826 | G33: 4.2868672 | H33: 5.2733048 | I33: 4.8512839 | J33: 4.3024348 | K33: 0.94334287 | L33: 3.078587 | M33: 3.7019804 | N33: 4.4586488 | O33: 4.7214011 | P33: 4.7576867 | Q33: 2.6844745 | R33: 4.0511469
A34: Admin | B34: 6.0636534 | C34: 5.5151407 | D34: 2.9803987 | E34: 5.6300085 | F34: 5.7355393 | G34: 3.0884943 | H34: 4.3223666 | I34: 5.2039021 | J34: 5.5605632 | K34: 6.5037411 | L34: 3.3437658 | M34: 4.318306 | N34: 4.4916477 | O34: 4.6731737 | P34: 5.0846127 | Q34: 4.6144317 | R34: 4.6996
A35: Segment Profits | B35: 24.161017 | C35: 25.315839 | D35: 22.280246 | E35: 21.370607 | F35: 20.1083 | G35: 27.404212 | H35: 25.116723 | I35: 15.045968 | J35: 29.122576 | K35: 35.285989 | L35: 34.299947 | M35: 43.421604 | N35: 23.628798 | O35: 23.33163 | P35: 23.64346 | Q35: 37.891474 | R35: 27.841549
A37: Budget | B37: 44583 | C37: 44614 | D37: 44642 | E37: 44673 | F37: 44703 | G37: 44734 | H37: 44764 | I37: 44795 | J37: 44826 | K37: 44856 | L37: 44887 | M37: 44917 | N37: Q1 FY22 | O37: Q2 FY22 | P37: Q3 FY22 | Q37: Q4 FY22 | R37: FY22
A38: Volume:
A39: Sales Vol (lbs mm) | B39: 213.40003 | C39: 236.82465 | D39: 363.37151 | E39: 231.54829 | F39: 229.47556 | G39: 279.85002 | H39: 220.50312 | I39: 233.10184 | J39: 285.61389 | K39: 285.51501 | L39: 364.18598 | M39: 360.92754 | N39: 813.59619 | O39: 740.87387 | P39: 739.21885 | Q39: 1010.6285 | R39: 3304.3174
A40: Sales Total | B40: 585.08473 | C40: 635.21347 | D40: 895.88101 | E40: 638.18123 | F40: 638.15555 | G40: 813.16597 | H40: 646.29463 | I40: 667.19484 | J40: 775.53532 | K40: 748.54295 | L40: 879.53584 | M40: 904.30845 | N40: 2116.1792 | O40: 2089.5027 | P40: 2089.0248 | Q40: 2532.3872 | R40: 8827.094
A41: SEGMENT PROFIT | B41: 52.171243 | C41: 57.764328 | D41: 77.235379 | E41: 60.589783 | F41: 63.6639 | G41: 82.536694 | H41: 47.842873 | I41: 53.308958 | J41: 69.325429 | K41: 83.966701 | L41: 106.39147 | M41: 110.16237 | N41: 187.17095 | O41: 206.79038 | P41: 170.47726 | Q41: 300.52054 | R41: 864.95913
A42: Gross Margin % | B42: 0.14276291 | C42: 0.14207204 | D42: 0.13085446 | E42: 0.14702437 | F42: 0.15146279 | G42: 0.14922217 | H42: 0.12471107 | I42: 0.1303213 | J42: 0.14098418 | K42: 0.15818289 | L42: 0.16020214 | M42: 0.16626793 | N42: 0.13751411 | O42: 0.14923522 | P42: 0.13254415 | Q42: 0.16177135 | R42: 0.14607159
A43: Segment Margin % | B43: 0.089168698 | C43: 0.090936876 | D43: 0.086211648 | E43: 0.094941344 | F43: 0.099762353 | G43: 0.10150043 | H43: 0.074026412 | I43: 0.079900136 | J43: 0.089390422 | K43: 0.11217352 | L43: 0.1209632 | M43: 0.12181946 | N43: 0.08844759 | O43: 0.09896631 | P43: 0.081606145 | Q43: 0.11867085 | R43: 0.097989115
A44: Per cwt
...
